Workbook

Sheet Census
A1: EMPLOYEE_ID | B1: GENDER | C1: DATE_OF_BIRTH | D1: DATE_OF_HIRE | E1: TERMINATION_DATE | F1: JOB_DURATION | G1: OCCUPATION | H1: SALARY | I1: Knowledge of Work | J1: Communication | K1: Teamwork | L1: Leadership | M1: Quality of Work | N1: Evaluation Score | O1: Evaluation Results
A2: 1238911001 | B2: Female | C2: 19112 | D2: 30963 | E2: 36488 | G2: Stocking Associate | H2: 31200 | I2: 3 | J2: 3 | K2: 2 | L2: 1 | M2: 1 | N2: =ROUND(AVERAGE(I2:M2),0) -> 2 | O2: =IF(N2=1,"Below Expectations",IF(N2=2,"Meets Expectations","Exceeds Expectations")) -> Meets Expectations
A3: 1238911002 | B3: Male | C3: 19833 | D3: 36350 | F3: =IF(E3="",DATEDIF(D3,TODAY(),"y")& "Years" &DATEDIF(D3,TODAY(),"ym")& "Months"&DATEDIF(D3,TODAY(),"md") &"Days",DATEDIF(D3,E3,"y")& "Years" &DATEDIF(D3,E3,"ym")& "Months"&DATEDIF(D3,E3,"md") &"Days") -> 26Years10Months4Days | G3: Stocking Associate | H3: 26000 | I3: 1 | J3: 3 | K3: 1 | L3: 1 | M3: 3 | N3: =ROUND(AVERAGE(I3:M3),0) -> 2 | O3: =IF(N3=1,"Below Expectations",IF(N3=2,"Meets Expectations","Exceeds Expectations")) -> Meets Expectations
A4: 1238911003 | B4: Female | C4: 20527 | D4: 33014 | G4: Stocking Associate | H4: 30602 | I4: 2 | J4: 3 | K4: 1 | L4: 1 | M4: 2 | N4: =ROUND(AVERAGE(I4:M4),0) -> 2 | O4: =IF(N4=1,"Below Expectations",IF(N4=2,"Meets Expectations","Exceeds Expectations")) -> Meets Expectations
A5: 1238911004 | B5: Female | C5: 20864 | D5: 36995 | G5: Warehouse Receiving Associate | H5: 29120 | I5: 2 | J5: 3 | K5: 2 | L5: 3 | M5: 1 | N5: =ROUND(AVERAGE(I5:M5),0) -> 2 | O5: =IF(N5=1,"Below Expectations",IF(N5=2,"Meets Expectations","Exceeds Expectations")) -> Meets Expectations
A6: 1238911005 | B6: Female | C6: 21034 | D6: 36006 | G6: Board Member | H6: 75000 | I6: 1 | J6: 2 | K6: 1 | L6: 1 | M6: 2 | N6: =ROUND(AVERAGE(I6:M6),0) -> 1 | O6: =IF(N6=1,"Below Expectations",IF(N6=2,"Meets Expectations","Exceeds Expectations")) -> Below Expectations
A7: 1238911006 | B7: Male | C7: 34706 | D7: 45441 | F7: =IF(E7="",DATEDIF(D7,TODAY(),"y")& "Years" &DATEDIF(D7,TODAY(),"ym")& "Months"&DATEDIF(D7,TODAY(),"md") &"Days",DATEDIF(D7,E7,"y")& "Years" &DATEDIF(D7,E7,"ym")& "Months"&DATEDIF(D7,E7,"md") &"Days") -> 1Years11Months14Days | G7: Customer Service Help Desk | H7: 46280 | I7: 3 | J7: 2 | K7: 3 | L7: 1 | M7: 1 | N7: =ROUND(AVERAGE(I7:M7),0) -> 2 | O7: =IF(N7=1,"Below Expectations",IF(N7=2,"Meets Expectations","Exceeds Expectations")) -> Meets Expectations
A8: 1238911007 | B8: Female | C8: 21223 | D8: 37919 | E8: 45735 | G8: Inventory Associate | H8: 27586 | I8: 3 | J8: 3 | K8: 1 | L8: 1 | M8: 3 | N8: =ROUND(AVERAGE(I8:M8),0) -> 2 | O8: =IF(N8=1,"Below Expectations",IF(N8=2,"Meets Expectations","Exceeds Expectations")) -> Meets Expectations
A9: 1238911008 | B9: Female | C9: 21236 | D9: 39081 | G9: Inventory Supervisor | H9: 67933.775 | I9: 3 | J9: 1 | K9: 2 | L9: 1 | M9: 3 | N9: =ROUND(AVERAGE(I9:M9),0) -> 2 | O9: =IF(N9=1,"Below Expectations",IF(N9=2,"Meets Expectations","Exceeds Expectations")) -> Meets Expectations
A10: 1238911009 | B10: Male | C10: 21283 | D10: 39668 | G10: Marketing Coordinator | H10: 67860 | I10: 3 | J10: 1 | K10: 1 | L10: 3 | M10: 3 | N10: =ROUND(AVERAGE(I10:M10),0) -> 2 | O10: =IF(N10=1,"Below Expectations",IF(N10=2,"Meets Expectations","Exceeds Expectations")) -> Meets Expectations
A11: 1238911010 | B11: Female | C11: 34729 | D11: 42711 | G11: Marketing Coordinator | H11: 67860 | I11: 3 | J11: 2 | K11: 3 | L11: 2 | M11: 2 | N11: =ROUND(AVERAGE(I11:M11),0) -> 2 | O11: =IF(N11=1,"Below Expectations",IF(N11=2,"Meets Expectations","Exceeds Expectations")) -> Meets Expectations
A12: 1238911011 | B12: Female | C12: 34051 | D12: 42958 | E12: 45662 | G12: Warehouse Receiving Associate | H12: 30030 | I12: 1 | J12: 1 | K12: 1 | L12: 2 | M12: 3 | N12: =ROUND(AVERAGE(I12:M12),0) -> 2 | O12: =IF(N12=1,"Below Expectations",IF(N12=2,"Meets Expectations","Exceeds Expectations")) -> Meets Expectations
A13: 1238911012 | B13: Female | C13: 21673 | D13: 38324 | E13: 44487 | G13: Stocking Associate | H13: 27456 | I13: 2 | J13: 3 | K13: 3 | L13: 2 | M13: 2 | N13: =ROUND(AVERAGE(I13:M13),0) -> 2 | O13: =IF(N13=1,"Below Expectations",IF(N13=2,"Meets Expectations","Exceeds Expectations")) -> Meets Expectations
A14: 1238911013 | B14: Female | C14: 35055 | D14: 44296 | G14: Stocking Associate | H14: 32864 | I14: 3 | J14: 2 | K14: 3 | L14: 3 | M14: 1 | N14: =ROUND(AVERAGE(I14:M14),0) -> 2 | O14: =IF(N14=1,"Below Expectations",IF(N14=2,"Meets Expectations","Exceeds Expectations")) -> Meets Expectations
A15: 1238911014 | B15: Female | C15: 21784 | D15: 36400 | G15: Stocking Associate | H15: 32864 | I15: 3 | J15: 2 | K15: 3 | L15: 3 | M15: 3 | N15: =ROUND(AVERAGE(I15:M15),0) -> 3 | O15: =IF(N15=1,"Below Expectations",IF(N15=2,"Meets Expectations","Exceeds Expectations")) -> Exceeds Expectations
A16: 1238911015 | B16: Male | C16: 21798 | D16: 38976 | E16: 41564 | F16: =IF(E16="",DATEDIF(D16,TODAY(),"y")& "Years" &DATEDIF(D16,TODAY(),"ym")& "Months"&DATEDIF(D16,TODAY(),"md") &"Days",DATEDIF(D16,E16,"y")& "Years" &DATEDIF(D16,E16,"ym")& "Months"&DATEDIF(D16,E16,"md") &"Days") -> 7Years1Months1Days | G16: Accountant | H16: 43914 | I16: 3 | J16: 2 | K16: 2 | L16: 2 | M16: 2 | N16: =ROUND(AVERAGE(I16:M16),0) -> 2 | O16: =IF(N16=1,"Below Expectations",IF(N16=2,"Meets Expectations","Exceeds Expectations")) -> Meets Expectations
A17: 1238911016 | B17: Male | C17: 31090 | D17: 41215 | E17: 43065 | F17: =IF(E17="",DATEDIF(D17,TODAY(),"y")& "Years" &DATEDIF(D17,TODAY(),"ym")& "Months"&DATEDIF(D17,TODAY(),"md") &"Days",DATEDIF(D17,E17,"y")& "Years" &DATEDIF(D17,E17,"ym")& "Months"&DATEDIF(D17,E17,"md") &"Days") -> 5Years0Months24Days | G17: Accounting Associate | H17: 43914 | I17: 1 | J17: 3 | K17: 1 | L17: 2 | M17: 2 | N17: =ROUND(AVERAGE(I17:M17),0) -> 2 | O17: =IF(N17=1,"Below Expectations",IF(N17=2,"Meets Expectations","Exceeds Expectations")) -> Meets Expectations
A18: 1238911017 | B18: Female | C18: 21825 | D18: 33014 | E18: 45619 | G18: Stocking Associate | H18: 26520 | I18: 2 | J18: 1 | K18: 3 | L18: 3 | M18: 1 | N18: =ROUND(AVERAGE(I18:M18),0) -> 2 | O18: =IF(N18=1,"Below Expectations",IF(N18=2,"Meets Expectations","Exceeds Expectations")) -> Meets Expectations
A19: 1238911018 | B19: Male | C19: 21846 | D19: 37904 | E19: 44297 | G19: Supervisor | H19: 74679.475 | I19: 3 | J19: 2 | K19: 1 | L19: 3 | M19: 1 | N19: =ROUND(AVERAGE(I19:M19),0) -> 2 | O19: =IF(N19=1,"Below Expectations",IF(N19=2,"Meets Expectations","Exceeds Expectations")) -> Meets Expectations
A20: 1238911019 | B20: Male | C20: 21903 | D20: 33014 | F20: =IF(E20="",DATEDIF(D20,TODAY(),"y")& "Years" &DATEDIF(D20,TODAY(),"ym")& "Months"&DATEDIF(D20,TODAY(),"md") &"Days",DATEDIF(D20,E20,"y")& "Years" &DATEDIF(D20,E20,"ym")& "Months"&DATEDIF(D20,E20,"md") &"Days") -> 35Years11Months22Days | G20: Stocking Associate | H20: 27300 | I20: 2 | J20: 3 | K20: 2 | L20: 2 | M20: 1 | N20: =ROUND(AVERAGE(I20:M20),0) -> 2 | O20: =IF(N20=1,"Below Expectations",IF(N20=2,"Meets Expectations","Exceeds Expectations")) -> Meets Expectations
A21: 1238911020 | B21: Female | C21: 21948 | D21: 38721 | G21: Senior Category Manager | H21: 107723.2 | I21: 2 | J21: 3 | K21: 3 | L21: 2 | M21: 3 | N21: =ROUND(AVERAGE(I21:M21),0) -> 3 | O21: =IF(N21=1,"Below Expectations",IF(N21=2,"Meets Expectations","Exceeds Expectations")) -> Exceeds Expectations
A22: 1238911021 | B22: Female | C22: 21958 | D22: 36183 | E22: 43695 | G22: Stocking Associate | H22: 27571.25 | I22: 2 | J22: 2 | K22: 1 | L22: 1 | M22: 3 | N22: =ROUND(AVERAGE(I22:M22),0) -> 2 | O22: =IF(N22=1,"Below Expectations",IF(N22=2,"Meets Expectations","Exceeds Expectations")) -> Meets Expectations
A23: 1238911022 | B23: Female | C23: 28244 | D23: 39815 | G23: Stocking Associate | H23: 27571.25 | I23: 1 | J23: 2 | K23: 1 | L23: 1 | M23: 3 | N23: =ROUND(AVERAGE(I23:M23),0) -> 2 | O23: =IF(N23=1,"Below Expectations",IF(N23=2,"Meets Expectations","Exceeds Expectations")) -> Meets Expectations
A24: 1238911023 | B24: Female | C24: 32709 | D24: 44571 | G24: Stocking Associate | H24: 30784 | I24: 3 | J24: 3 | K24: 3 | L24: 2 | M24: 3 | N24: =ROUND(AVERAGE(I24:M24),0) -> 3 | O24: =IF(N24=1,"Below Expectations",IF(N24=2,"Meets Expectations","Exceeds Expectations")) -> Exceeds Expectations
A25: 1238911024 | B25: Female | C25: 22118 | D25: 37105 | G25: Stocking Associate | H25: 27300 | I25: 3 | J25: 2 | K25: 2 | L25: 2 | M25: 2 | N25: =ROUND(AVERAGE(I25:M25),0) -> 2 | O25: =IF(N25=1,"Below Expectations",IF(N25=2,"Meets Expectations","Exceeds Expectations")) -> Meets Expectations
A26: 1238911025 | B26: Female | C26: 22138 | D26: 36423 | G26: Inventory Supervisor | H26: 65000 | I26: 2 | J26: 1 | K26: 2 | L26: 3 | M26: 3 | N26: =ROUND(AVERAGE(I26:M26),0) -> 2 | O26: =IF(N26=1,"Below Expectations",IF(N26=2,"Meets Expectations","Exceeds Expectations")) -> Meets Expectations
A27: 1238911026 | B27: Female | C27: 22180 | D27: 37729 | G27: Inventory Retrieving Associate | H27: 28596.975 | I27: 1 | J27: 1 | K27: 3 | L27: 1 | M27: 1 | N27: =ROUND(AVERAGE(I27:M27),0) -> 1 | O27: =IF(N27=1,"Below Expectations",IF(N27=2,"Meets Expectations","Exceeds Expectations")) -> Below Expectations
A28: 1238911027 | B28: Female | C28: 22190 | D28: 40172 | G28: Manager of Operations | H28: 101936.25 | I28: 2 | J28: 2 | K28: 2 | L28: 2 | M28: 2 | N28: =ROUND(AVERAGE(I28:M28),0) -> 2 | O28: =IF(N28=1,"Below Expectations",IF(N28=2,"Meets Expectations","Exceeds Expectations")) -> Meets Expectations
A29: 1238911028 | B29: Female | C29: 22293 | D29: 36294 | G29: Field App Engineer | H29: 93062.5 | I29: 1 | J29: 3 | K29: 3 | L29: 1 | M29: 1 | N29: =ROUND(AVERAGE(I29:M29),0) -> 2 | O29: =IF(N29=1,"Below Expectations",IF(N29=2,"Meets Expectations","Exceeds Expectations")) -> Meets Expectations
A30: 1238911029 | B30: Male | C30: 22295 | D30: 35783 | F30: =IF(E30="",DATEDIF(D30,TODAY(),"y")& "Years" &DATEDIF(D30,TODAY(),"ym")& "Months"&DATEDIF(D30,TODAY(),"md") &"Days",DATEDIF(D30,E30,"y")& "Years" &DATEDIF(D30,E30,"ym")& "Months"&DATEDIF(D30,E30,"md") &"Days") -> 28Years4Months24Days | G30: Stocking Associate | H30: 27404 | I30: 3 | J30: 1 | K30: 3 | L30: 3 | M30: 1 | N30: =ROUND(AVERAGE(I30:M30),0) -> 2 | O30: =IF(N30=1,"Below Expectations",IF(N30=2,"Meets Expectations","Exceeds Expectations")) -> Meets Expectations
A31: 1238911030 | B31: Male | C31: 36769 | D31: 45631 | F31: =IF(E31="",DATEDIF(D31,TODAY(),"y")& "Years" &DATEDIF(D31,TODAY(),"ym")& "Months"&DATEDIF(D31,TODAY(),"md") &"Days",DATEDIF(D31,E31,"y")& "Years" &DATEDIF(D31,E31,"ym")& "Months"&DATEDIF(D31,E31,"md") &"Days") -> 1Years5Months8Days | G31: Stocking Associate | H31: 27404 | I31: 2 | J31: 3 | K31: 2 | L31: 2 | M31: 1 | N31: =ROUND(AVERAGE(I31:M31),0) -> 2 | O31: =IF(N31=1,"Below Expectations",IF(N31=2,"Meets Expectations","Exceeds Expectations")) -> Meets Expectations
A32: 1238911031 | B32: Female | C32: 22323 | D32: 36353 | G32: Senior Copywriter | H32: 82875 | I32: 1 | J32: 1 | K32: 2 | L32: 3 | M32: 1 | N32: =ROUND(AVERAGE(I32:M32),0) -> 2 | O32: =IF(N32=1,"Below Expectations",IF(N32=2,"Meets Expectations","Exceeds Expectations")) -> Meets Expectations
A33: 1238911032 | B33: Male | C33: 36193 | D33: 45285 | F33: =IF(E33="",DATEDIF(D33,TODAY(),"y")& "Years" &DATEDIF(D33,TODAY(),"ym")& "Months"&DATEDIF(D33,TODAY(),"md") &"Days",DATEDIF(D33,E33,"y")& "Years" &DATEDIF(D33,E33,"ym")& "Months"&DATEDIF(D33,E33,"md") &"Days") -> 2Years4Months18Days | G33: Stocking Associate | H33: 27300 | I33: 1 | J33: 3 | K33: 1 | L33: 3 | M33: 3 | N33: =ROUND(AVERAGE(I33:M33),0) -> 2 | O33: =IF(N33=1,"Below Expectations",IF(N33=2,"Meets Expectations","Exceeds Expectations")) -> Meets Expectations
A34: 1238911033 | B34: Male | C34: 22413 | D34: 33014 | E34: 42730 | F34: =IF(E34="",DATEDIF(D34,TODAY(),"y")& "Years" &DATEDIF(D34,TODAY(),"ym")& "Months"&DATEDIF(D34,TODAY(),"md") &"Days",DATEDIF(D34,E34,"y")& "Years" &DATEDIF(D34,E34,"ym")& "Months"&DATEDIF(D34,E34,"md") &"Days") -> 26Years7Months5Days | G34: Stocking Associate | H34: 27300 | I34: 2 | J34: 2 | K34: 3 | L34: 2 | M34: 1 | N34: =ROUND(AVERAGE(I34:M34),0) -> 2 | O34: =IF(N34=1,"Below Expectations",IF(N34=2,"Meets Expectations","Exceeds Expectations")) -> Meets Expectations
A35: 1238911034 | B35: Female | C35: 22414 | D35: 37476 | G35: Inventory Retrieving Associate | H35: 28808 | I35: 2 | J35: 1 | K35: 2 | L35: 1 | M35: 2 | N35: =ROUND(AVERAGE(I35:M35),0) -> 2 | O35: =IF(N35=1,"Below Expectations",IF(N35=2,"Meets Expectations","Exceeds Expectations")) -> Meets Expectations
A36: 1238911035 | B36: Female | C36: 22454 | D36: 39338 | G36: Inventory Supervisor | H36: 60797.1 | I36: 2 | J36: 3 | K36: 3 | L36: 2 | M36: 3 | N36: =ROUND(AVERAGE(I36:M36),0) -> 3 | O36: =IF(N36=1,"Below Expectations",IF(N36=2,"Meets Expectations","Exceeds Expectations")) -> Exceeds Expectations
A37: 1238911036 | B37: Male | C37: 22482 | D37: 39788 | F37: =IF(E37="",DATEDIF(D37,TODAY(),"y")& "Years" &DATEDIF(D37,TODAY(),"ym")& "Months"&DATEDIF(D37,TODAY(),"md") &"Days",DATEDIF(D37,E37,"y")& "Years" &DATEDIF(D37,E37,"ym")& "Months"&DATEDIF(D37,E37,"md") &"Days") -> 17Years5Months7Days | G37: Agent Quality Control Monitoring | H37: 48490 | I37: 2 | J37: 3 | K37: 3 | L37: 2 | M37: 3 | N37: =ROUND(AVERAGE(I37:M37),0) -> 3 | O37: =IF(N37=1,"Below Expectations",IF(N37=2,"Meets Expectations","Exceeds Expectations")) -> Exceeds Expectations
A38: 1238911037 | B38: Male | C38: 22501 | D38: 39906 | F38: =IF(E38="",DATEDIF(D38,TODAY(),"y")& "Years" &DATEDIF(D38,TODAY(),"ym")& "Months"&DATEDIF(D38,TODAY(),"md") &"Days",DATEDIF(D38,E38,"y")& "Years" &DATEDIF(D38,E38,"ym")& "Months"&DATEDIF(D38,E38,"md") &"Days") -> 17Years1Months10Days | G38: Stocking Associate | H38: 28782 | I38: 2 | J38: 2 | K38: 1 | L38: 3 | M38: 1 | N38: =ROUND(AVERAGE(I38:M38),0) -> 2 | O38: =IF(N38=1,"Below Expectations",IF(N38=2,"Meets Expectations","Exceeds Expectations")) -> Meets Expectations
A39: 1238911038 | B39: Female | C39: 24539 | D39: 36294 | G39: Stocking Associate | H39: 28782 | I39: 2 | J39: 3 | K39: 3 | L39: 2 | M39: 2 | N39: =ROUND(AVERAGE(I39:M39),0) -> 2 | O39: =IF(N39=1,"Below Expectations",IF(N39=2,"Meets Expectations","Exceeds Expectations")) -> Meets Expectations
A40: 1238911039 | B40: Female | C40: 22507 | D40: 37779 | G40: Inventory Retrieving Associate | H40: 30446 | I40: 2 | J40: 3 | K40: 2 | L40: 1 | M40: 1 | N40: =ROUND(AVERAGE(I40:M40),0) -> 2 | O40: =IF(N40=1,"Below Expectations",IF(N40=2,"Meets Expectations","Exceeds Expectations")) -> Meets Expectations
...

Sheet Female_Employees
A1: 1238911001 | B1: Female | C1: 19112 | D1: 30963 | E1: 36488 | F1: Stocking Associate | G1: 31200 | H1: 3 | I1: 3 | J1: 2 | K1: 1 | L1: 1
A2: 1238911003 | B2: Female | C2: 20527 | D2: 33014 | F2: Stocking Associate | G2: 30602 | H2: 2 | I2: 3 | J2: 1 | K2: 1 | L2: 2
A3: 1238911004 | B3: Female | C3: 20864 | D3: 36995 | F3: Warehouse Receiving Associate | G3: 29120 | H3: 2 | I3: 3 | J3: 2 | K3: 3 | L3: 1
A4: 1238911005 | B4: Female | C4: 21034 | D4: 36006 | F4: Board Member | G4: 75000 | H4: 1 | I4: 2 | J4: 1 | K4: 1 | L4: 2
A5: 1238911007 | B5: Female | C5: 21223 | D5: 37919 | E5: 45735 | F5: Inventory Associate | G5: 27586 | H5: 3 | I5: 3 | J5: 1 | K5: 1 | L5: 3
A6: 1238911008 | B6: Female | C6: 21236 | D6: 39081 | F6: Inventory Supervisor | G6: 67933.775 | H6: 3 | I6: 1 | J6: 2 | K6: 1 | L6: 3
A7: 1238911010 | B7: Female | C7: 34729 | D7: 42711 | F7: Marketing Coordinator | G7: 67860 | H7: 3 | I7: 2 | J7: 3 | K7: 2 | L7: 2
A8: 1238911011 | B8: Female | C8: 34051 | D8: 42958 | E8: 45662 | F8: Warehouse Receiving Associate | G8: 30030 | H8: 1 | I8: 1 | J8: 1 | K8: 2 | L8: 3
A9: 1238911012 | B9: Female | C9: 21673 | D9: 38324 | E9: 44487 | F9: Stocking Associate | G9: 27456 | H9: 2 | I9: 3 | J9: 3 | K9: 2 | L9: 2
A10: 1238911013 | B10: Female | C10: 35055 | D10: 44296 | F10: Stocking Associate | G10: 32864 | H10: 3 | I10: 2 | J10: 3 | K10: 3 | L10: 1
A11: 1238911014 | B11: Female | C11: 21784 | D11: 36400 | F11: Stocking Associate | G11: 32864 | H11: 3 | I11: 2 | J11: 3 | K11: 3 | L11: 3
A12: 1238911017 | B12: Female | C12: 21825 | D12: 33014 | E12: 45619 | F12: Stocking Associate | G12: 26520 | H12: 2 | I12: 1 | J12: 3 | K12: 3 | L12: 1
A13: 1238911020 | B13: Female | C13: 21948 | D13: 38721 | F13: Senior Category Manager | G13: 107723.2 | H13: 2 | I13: 3 | J13: 3 | K13: 2 | L13: 3
A14: 1238911021 | B14: Female | C14: 21958 | D14: 36183 | E14: 43695 | F14: Stocking Associate | G14: 27571.25 | H14: 2 | I14: 2 | J14: 1 | K14: 1 | L14: 3
A15: 1238911022 | B15: Female | C15: 28244 | D15: 39815 | F15: Stocking Associate | G15: 27571.25 | H15: 1 | I15: 2 | J15: 1 | K15: 1 | L15: 3
A16: 1238911023 | B16: Female | C16: 32709 | D16: 44571 | F16: Stocking Associate | G16: 30784 | H16: 3 | I16: 3 | J16: 3 | K16: 2 | L16: 3
A17: 1238911024 | B17: Female | C17: 22118 | D17: 37105 | F17: Stocking Associate | G17: 27300 | H17: 3 | I17: 2 | J17: 2 | K17: 2 | L17: 2
A18: 1238911025 | B18: Female | C18: 22138 | D18: 36423 | F18: Inventory Supervisor | G18: 65000 | H18: 2 | I18: 1 | J18: 2 | K18: 3 | L18: 3
A19: 1238911026 | B19: Female | C19: 22180 | D19: 37729 | F19: Inventory Retrieving Associate | G19: 28596.975 | H19: 1 | I19: 1 | J19: 3 | K19: 1 | L19: 1
A20: 1238911027 | B20: Female | C20: 22190 | D20: 40172 | F20: Manager of Operations | G20: 101936.25 | H20: 2 | I20: 2 | J20: 2 | K20: 2 | L20: 2
A21: 1238911028 | B21: Female | C21: 22293 | D21: 36294 | F21: Field App Engineer | G21: 93062.5 | H21: 1 | I21: 3 | J21: 3 | K21: 1 | L21: 1
A22: 1238911031 | B22: Female | C22: 22323 | D22: 36353 | F22: Senior Copywriter | G22: 82875 | H22: 1 | I22: 1 | J22: 2 | K22: 3 | L22: 1
A23: 1238911034 | B23: Female | C23: 22414 | D23: 37476 | F23: Inventory Retrieving Associate | G23: 28808 | H23: 2 | I23: 1 | J23: 2 | K23: 1 | L23: 2
A24: 1238911035 | B24: Female | C24: 22454 | D24: 39338 | F24: Inventory Supervisor | G24: 60797.1 | H24: 2 | I24: 3 | J24: 3 | K24: 2 | L24: 3
A25: 1238911038 | B25: Female | C25: 24539 | D25: 36294 | F25: Stocking Associate | G25: 28782 | H25: 2 | I25: 3 | J25: 3 | K25: 2 | L25: 2
A26: 1238911039 | B26: Female | C26: 22507 | D26: 37779 | F26: Inventory Retrieving Associate | G26: 30446 | H26: 2 | I26: 3 | J26: 2 | K26: 1 | L26: 1
A27: 1238911043 | B27: Female | C27: 22534 | D27: 33014 | E27: 41666 | F27: Inventory Cycle Associate | G27: 30238 | H27: 1 | I27: 2 | J27: 2 | K27: 1 | L27: 3
A28: 1238911044 | B28: Female | C28: 22709 | D28: 36498 | F28: Stocking Associate | G28: 28106 | H28: 1 | I28: 1 | J28: 3 | K28: 3 | L28: 3
A29: 1238911045 | B29: Female | C29: 22798 | D29: 36400 | F29: Stocking Associate | G29: 29510 | H29: 1 | I29: 2 | J29: 2 | K29: 3 | L29: 2
A30: 1238911046 | B30: Female | C30: 22718 | D30: 38976 | F30: Stocking Associate | G30: 30524 | H30: 3 | I30: 1 | J30: 3 | K30: 2 | L30: 3
A31: 1238911054 | B31: Female | C31: 23077 | D31: 37105 | F31: Stocking Associate | G31: 30446 | H31: 3 | I31: 3 | J31: 3 | K31: 2 | L31: 3
A32: 1238911055 | B32: Female | C32: 22465 | D32: 33014 | E32: 42422 | F32: Stocking Associate | G32: 30446 | H32: 1 | I32: 3 | J32: 2 | K32: 2 | L32: 1
A33: 1238911056 | B33: Female | C33: 23089 | D33: 44459 | E33: 45478 | F33: Stocking Associate | G33: 31616 | H33: 3 | I33: 2 | J33: 3 | K33: 2 | L33: 3
A34: 1238911059 | B34: Female | C34: 23210 | D34: 35783 | F34: Dir Content Operation | G34: 152059.7 | H34: 2 | I34: 2 | J34: 3 | K34: 2 | L34: 2
A35: 1238911060 | B35: Female | C35: 24871 | D35: 36353 | E35: 43604 | F35: Warehouse Supervisor | G35: 75337.275 | H35: 3 | I35: 1 | J35: 2 | K35: 1 | L35: 3
A36: 1238911061 | B36: Female | C36: 23215 | D36: 40386 | F36: Warehouse Supervisor | G36: 75337.275 | H36: 1 | I36: 1 | J36: 3 | K36: 1 | L36: 1
A37: 1238911066 | B37: Female | C37: 25209 | D37: 42462 | E37: 43743 | F37: Stocking Associate | G37: 27404 | H37: 1 | I37: 2 | J37: 2 | K37: 2 | L37: 1
A38: 1238911069 | B38: Female | C38: 23563 | D38: 43464 | E38: 44662 | F38: Stocking Associate | G38: 28340 | H38: 3 | I38: 1 | J38: 3 | K38: 1 | L38: 2
A39: 1238911070 | B39: Female | C39: 23598 | D39: 39668 | F39: Stocking Associate | G39: 29198 | H39: 2 | I39: 1 | J39: 3 | K39: 1 | L39: 3
A40: 1238911074 | B40: Female | C40: 23659 | D40: 36400 | F40: Stocking Associate | G40: 27300 | H40: 1 | I40: 2 | J40: 1 | K40: 2 | L40: 2
...

Sheet Male_Employees
A1: 1238911002 | B1: Male | C1: 19833 | D1: 36350 | F1: Stocking Associate | G1: 26000 | H1: 1 | I1: 3 | J1: 1 | K1: 1 | L1: 3
A2: 1238911006 | B2: Male | C2: 34706 | D2: 45441 | F2: Customer Service Help Desk | G2: 46280 | H2: 3 | I2: 2 | J2: 3 | K2: 1 | L2: 1
A3: 1238911009 | B3: Male | C3: 21283 | D3: 39668 | F3: Marketing Coordinator | G3: 67860 | H3: 3 | I3: 1 | J3: 1 | K3: 3 | L3: 3
A4: 1238911015 | B4: Male | C4: 21798 | D4: 38976 | E4: 41564 | F4: Accountant | G4: 43914 | H4: 3 | I4: 2 | J4: 2 | K4: 2 | L4: 2
A5: 1238911016 | B5: Male | C5: 31090 | D5: 41215 | E5: 43065 | F5: Accounting Associate | G5: 43914 | H5: 1 | I5: 3 | J5: 1 | K5: 2 | L5: 2
A6: 1238911018 | B6: Male | C6: 21846 | D6: 37904 | E6: 44297 | F6: Supervisor | G6: 74679.475 | H6: 3 | I6: 2 | J6: 1 | K6: 3 | L6: 1
A7: 1238911019 | B7: Male | C7: 21903 | D7: 33014 | F7: Stocking Associate | G7: 27300 | H7: 2 | I7: 3 | J7: 2 | K7: 2 | L7: 1
A8: 1238911029 | B8: Male | C8: 22295 | D8: 35783 | F8: Stocking Associate | G8: 27404 | H8: 3 | I8: 1 | J8: 3 | K8: 3 | L8: 1
A9: 1238911030 | B9: Male | C9: 36769 | D9: 45631 | F9: Stocking Associate | G9: 27404 | H9: 2 | I9: 3 | J9: 2 | K9: 2 | L9: 1
A10: 1238911032 | B10: Male | C10: 36193 | D10: 45285 | F10: Stocking Associate | G10: 27300 | H10: 1 | I10: 3 | J10: 1 | K10: 3 | L10: 3
A11: 1238911033 | B11: Male | C11: 22413 | D11: 33014 | E11: 42730 | F11: Stocking Associate | G11: 27300 | H11: 2 | I11: 2 | J11: 3 | K11: 2 | L11: 1
A12: 1238911036 | B12: Male | C12: 22482 | D12: 39788 | F12: Agent Quality Control Monitoring | G12: 48490 | H12: 2 | I12: 3 | J12: 3 | K12: 2 | L12: 3
A13: 1238911037 | B13: Male | C13: 22501 | D13: 39906 | F13: Stocking Associate | G13: 28782 | H13: 2 | I13: 2 | J13: 1 | K13: 3 | L13: 1
A14: 1238911040 | B14: Male | C14: 22513 | D14: 38284 | E14: 45539 | F14: Accountant AP | G14: 48317.5 | H14: 1 | I14: 1 | J14: 2 | K14: 2 | L14: 2
A15: 1238911041 | B15: Male | C15: 22555 | D15: 39081 | F15: Inventory Retrieving Associate | G15: 31044 | H15: 3 | I15: 3 | J15: 1 | K15: 1 | L15: 1
A16: 1238911042 | B16: Male | C16: 22532 | D16: 39668 | F16: Stocking Associate | G16: 30732 | H16: 3 | I16: 2 | J16: 3 | K16: 2 | L16: 2
A17: 1238911047 | B17: Male | C17: 22823 | D17: 39846 | F17: Customer Service Associate | G17: 35139 | H17: 1 | I17: 2 | J17: 1 | K17: 1 | L17: 3
A18: 1238911048 | B18: Male | C18: 22858 | D18: 37904 | F18: Shipping Associate | G18: 27300 | H18: 1 | I18: 2 | J18: 1 | K18: 1 | L18: 2
A19: 1238911049 | B19: Male | C19: 26991 | D19: 38664 | F19: Stocking Associate | G19: 27300 | H19: 2 | I19: 1 | J19: 3 | K19: 1 | L19: 2
A20: 1238911050 | B20: Male | C20: 22888 | D20: 40019 | F20: Stocking Associate | G20: 27664 | H20: 2 | I20: 3 | J20: 2 | K20: 1 | L20: 3
A21: 1238911051 | B21: Male | C21: 22932 | D21: 38721 | F21: Inventory Retrieving Associate | G21: 29822.5 | H21: 2 | I21: 1 | J21: 3 | K21: 2 | L21: 2
A22: 1238911052 | B22: Male | C22: 22997 | D22: 38009 | F22: Customer Service Help Desk | G22: 33800 | H22: 3 | I22: 2 | J22: 3 | K22: 2 | L22: 3
A23: 1238911053 | B23: Male | C23: 23036 | D23: 36535 | F23: Stocking Associate | G23: 31460 | H23: 3 | I23: 3 | J23: 3 | K23: 1 | L23: 2
A24: 1238911057 | B24: Male | C24: 23153 | D24: 40172 | F24: Inventory Transfer Associate | G24: 29900 | H24: 3 | I24: 3 | J24: 1 | K24: 3 | L24: 2
A25: 1238911058 | B25: Male | C25: 23012 | D25: 37729 | F25: Inventory Retrieving Associate | G25: 27404 | H25: 2 | I25: 1 | J25: 3 | K25: 3 | L25: 2
A26: 1238911062 | B26: Male | C26: 23237 | D26: 37476 | F26: Stocking Associate | G26: 27300 | H26: 2 | I26: 2 | J26: 3 | K26: 1 | L26: 3
... A30: 1238911067 | B30: Male | C30: 23468 | D30: 37779 | F30: Customer Service Associate | G30: 27569.325 | H30: 1 | I30: 1 | J30: 1 | K30: 2 | L30: 1
A31: 1238911068 | B31: Male | C31: 23493 | D31: 42667 | E31: 43382 | F31: Customer Service Associate | G31: 30706 | H31: 2 | I31: 1 | J31: 3 | K31: 2 | L31: 3
A32: 1238911071 | B32: Male | C32: 23621 | D32: 37114 | F32: Stocking Associate | G32: 26650 | H32: 3 | I32: 1 | J32: 3 | K32: 2 | L32: 1
A33: 1238911072 | B33: Male | C33: 23647 | D33: 36498 | F33: Inventory Retrieving Associate | G33: 32266 | H33: 2 | I33: 3 | J33: 1 | K33: 3 | L33: 3
A34: 1238911073 | B34: Male | C34: 23680 | D34: 44455 | E34: 45171 | F34: Inventory Retrieving Associate | G34: 32266 | H34: 3 | I34: 2 | J34: 3 | K34: 2 | L34: 2
A35: 1238911076 | B35: Male | C35: 23719 | D35: 37904 | F35: Stocking Associate | G35: 27300 | H35: 2 | I35: 3 | J35: 1 | K35: 1 | L35: 1
A36: 1238911077 | B36: Male | C36: 23732 | D36: 40019 | F36: Stocking Associate | G36: 27300 | H36: 1 | I36: 3 | J36: 1 | K36: 3 | L36: 2
A37: 1238911078 | B37: Male | C37: 23876 | D37: 38009 | E37: 45201 | F37: Manager of Operations | G37: 77809.225 | H37: 3 | I37: 3 | J37: 2 | K37: 1 | L37: 3
A38: 1238911080 | B38: Male | C38: 24076 | D38: 37105 | E38: 42146 | F38: Warehouse Supervisor | G38: 59097.675 | H38: 1 | I38: 1 | J38: 3 | K38: 1 | L38: 2
A39: 1238911083 | B39: Male | C39: 24037 | D39: 40172 | F39: Stocking Associate | G39: 28782 | H39: 1 | I39: 2 | J39: 2 | K39: 3 | L39: 2
A40: 1238911085 | B40: Male | C40: 24045 | D40: 35783 | F40: Stocking Associate | G40: 26520 | H40: 2 | I40: 3 | J40: 2 | K40: 1 | L40: 2
A41: 1238911087 | B41: Male | C41: 24086 | D41: 40386 | F41: Stocking Associate | G41: 28210 | H41: 1 | I41: 2 | J41: 2 | K41: 1 | L41: 1
A42: 1238911088 | B42: Male | C42: 24112 | D42: 43320 | E42: 44125 | F42: Inventory Retrieving Associate | G42: 27586 | H42: 3 | I42: 1 | J42: 2 | K42: 2 | L42: 2
A43: 1238911090 | B43: Male | C43: 24134 | D43: 40471 | F43: Stocking Associate | G43: 27300 | H43: 2 | I43: 3 | J43: 1 | K43: 1 | L43: 3
...

Sheet Occupation_Pivot
A3: Row Labels | B3: Sum of EMPLOYEE_ID
A4: Stocking Associate | B4: 130085671549
A5: Inventory Retrieving Associate | B5: 45839716945
A6: Customer Service Representative | B6: 43361900630
A7: Category Manager | B7: 26017141027
A8: Merchandiser | B8: 18583673625
A9: Account Executive Small Accounts | B9: 18583671398
A10: Warehouse Associate | B10: 18583669221
A11: Agent Support Desk Customer Service | B11: 13628026690
A12: Administrator Purchasing | B12: 12389114487
A13: Engineer Application Developer | B13: 11150203615
A14: Assoc Will Call Center | B14: 11150203061
A15: Customer Service Associate | B15: 11150200231
... A310: Board Member | B310: 1238911005
A311: (blank)
A312: Grand Total | B312: 925466796378

Sheet Salary_Pivot
A3: Row Labels | B3: Max of SALARY
A4: Female | B4: 425199.78
A5: Account Executive | B5: 65625
A6: Account Executive Regional Accounts | B6: 66300
A7: Account Executive Small Accounts | B7: 50239.95
A8: Account Manager | B8: 71292.5
A9: Account Mgr Marketplace | B9: 68770
A10: Account Mgr Small Business Accounts | B10: 68750
A11: Administrative Assistant | B11: 37128
A12: Administrator Purchasing | B12: 68750
A13: Agent Public Image Customer Service | B13: 32396
A14: Agent QC Monitoring | B14: 44200
A15: Agent Support Desk Customer Service | B15: 31590
... A354: Web Designer | B354: 66912.5
A355: (blank)
A356: (blank)
A357: Grand Total | B357: 425199.78

Sheet Data_Analysis
A1: Data Analysis
A2: Salary Comparison Report
A3: Total Number of Male Employees | E3: =COUNTIF(Census!B:B,"Male") -> 321
A4: Total Number of Female Employees | E4: =COUNTIF(Census!B:B,"Female") -> 426
A5: Total Number of Employees | E5: =E3+E4 -> 747
A6: Salary Bracket
C7: Count | E7: Percentage
A8: Salary Bracket | C8: Male | D8: Female | E8: Male | F8: Female
A9: $20,000-$50,000 | C9: =COUNTIFS(Census!H:H,">=20000",Census!H:H,"<=50000", Census!B:B, "Male") -> 196 | D9: =COUNTIFS(Census!H:H,">=20000",Census!H:H,"<=50000", Census!B:B, "Female") -> 164 | E9: =C9/E5 -> 0.26238286 | F9: =D9/E5 -> 0.21954485
A10: $50,001-$100,000 | C10: =COUNTIFS(Census!H:H,">=50001",Census!H:H,"<=100000", Census!B:B, "Male") -> 110 | D10: =COUNTIFS(Census!H:H,">=50001",Census!H:H,"<=100000",Census!B:B,"Female") -> 203 | E10: =C10/E5 -> 0.14725569 | F10: =D10/E5 -> 0.27175368
A11: $100,001-200,000 | C11: =COUNTIFS(Census!H:H,">=100001",Census!H:H,"<=200000", Census!B:B, "Male") -> 13 | D11: =COUNTIFS(Census!H:H,">=100001",Census!H:H,"<=200000", Census!B:B, "Female") -> 51 | E11: =C11/E5 -> 0.017402945 | F11: =D11/E5 -> 0.068273092
A12: $200,001-300,000 | C12: =COUNTIFS(Census!H:H,">=200001",Census!H:H,"<=300000", Census!B:B, "Male") -> 2 | D12: =COUNTIFS(Census!H:H,">=200001",Census!H:H,"<=300000", Census!B:B, "Female") -> 5 | E12: =C12/E5 -> 0.0026773762 | F12: =D12/E5 -> 0.0066934404
A13: $300,001-400,000 | C13: =COUNTIFS(Census!H:H,">=300001",Census!H:H,"<=400000", Census!B:B, "Male") -> 0 | D13: =COUNTIFS(Census!H:H,">=300001",Census!H:H,"<=400000", Census!B:B, "Female") -> 2 | E13: =C13/E5 -> 0 | F13: =D13/E5 -> 0.0026773762
A14: Average Salary by Occupation
C15: Count | E15: Avg Salary
A16: Occupation | C16: Male | D16: Female | E16: Male | F16: Female
A17: Stocking Associate | C17: =COUNTIFS(Census!G:G,A17,Census!B:B,"Male") -> 60 | D17: =COUNTIFS(Census!G:G,A17,Census!B:B,"Female") -> 45 | E17: =AVERAGEIFS(Census!$H:$H,Census!$G:$G,$A17,Census!$B:$B,"Male") -> 28310.542 | F17: =AVERAGEIFS(Census!$H:$H,Census!$G:$G,$A17,Census!$B:$B,"Female") -> 29874.5
A18: Inventory Retrieving Associate | C18: =COUNTIFS(Census!G:G,A18,Census!B:B,"Male") -> 26 | D18: =COUNTIFS(Census!G:G,A18,Census!B:B,"Female") -> 11 | E18: =AVERAGEIFS(Census!$H:$H,Census!$G:$G,$A18,Census!$B:$B,"Male") -> 28510.442 | F18: =AVERAGEIFS(Census!$H:$H,Census!$G:$G,$A18,Census!$B:$B,"Female") -> 29183.543
A19: Customer Service Representative | C19: =COUNTIFS(Census!G:G,A19,Census!B:B,"Male") -> 22 | D19: =COUNTIFS(Census!G:G,A19,Census!B:B,"Female") -> 13 | E19: =AVERAGEIFS(Census!$H:$H,Census!$G:$G,$A19,Census!$B:$B,"Male") -> 30798.795 | F19: =AVERAGEIFS(Census!$H:$H,Census!$G:$G,$A19,Census!$B:$B,"Female") -> 33489.788
A20: Category Manager | C20: =COUNTIFS(Census!G:G,A20,Census!B:B,"Male") -> 6 | D20: =COUNTIFS(Census!G:G,A20,Census!B:B,"Female") -> 15 | E20: =AVERAGEIFS(Census!$H:$H,Census!$G:$G,$A20,Census!$B:$B,"Male") -> 79052.263 | F20: =AVERAGEIFS(Census!$H:$H,Census!$G:$G,$A20,Census!$B:$B,"Female") -> 82293.745
A21: Top 10 Highest Paid Positions
C22: Salary
A23: Occupation | C23: Male | D23: Female
A24: Sr. VP Sales & Marketing | C24: =SUMIFS(Census!$H:$H,Census!$G:$G,$A24,Census!$B:$B,"Male") -> 0 | D24: =SUMIFS(Census!$H:$H,Census!$G:$G,$A24,Census!$B:$B,"Female") -> 425199.78
A25: Chief Legal Officer Corporate Legal | C25: =SUMIFS(Census!$H:$H,Census!$G:$G,$A25,Census!$B:$B,"Male") -> 0 | D25: =SUMIFS(Census!$H:$H,Census!$G:$G,$A25,Census!$B:$B,"Female") -> 380842.47
A26: Sr. VP Operations | C26: =SUMIFS(Census!$H:$H,Census!$G:$G,$A26,Census!$B:$B,"Male") -> 0 | D26: =SUMIFS(Census!$H:$H,Census!$G:$G,$A26,Census!$B:$B,"Female") -> 343331.95
A27: Chairman Holding | C27: =SUMIFS(Census!$H:$H,Census!$G:$G,$A27,Census!$B:$B,"Male") -> 0 | D27: =SUMIFS(Census!$H:$H,Census!$G:$G,$A27,Census!$B:$B,"Female") -> 281250
A28: General Counsel | C28: =SUMIFS(Census!$H:$H,Census!$G:$G,$A28,Census!$B:$B,"Male") -> 0 | D28: =SUMIFS(Census!$H:$H,Census!$G:$G,$A28,Census!$B:$B,"Female") -> 262650.05
A29: CFO NA Region | C29: =SUMIFS(Census!$H:$H,Census!$G:$G,$A29,Census!$B:$B,"Male") -> 0 | D29: =SUMIFS(Census!$H:$H,Census!$G:$G,$A29,Census!$B:$B,"Female") -> 260100.1
A30: VP International | C30: =SUMIFS(Census!$H:$H,Census!$G:$G,$A30,Census!$B:$B,"Male") -> 0 | D30: =SUMIFS(Census!$H:$H,Census!$G:$G,$A30,Census!$B:$B,"Female") -> 246281.25
A31: VP Marketplace | C31: =SUMIFS(Census!$H:$H,Census!$G:$G,$A31,Census!$B:$B,"Male") -> 231875 | D31: =SUMIFS(Census!$H:$H,Census!$G:$G,$A31,Census!$B:$B,"Female") -> 0
A32: VP Admin Sales and Mktg | C32: =SUMIFS(Census!$H:$H,Census!$G:$G,$A32,Census!$B:$B,"Male") -> 225205.18 | D32: =SUMIFS(Census!$H:$H,Census!$G:$G,$A32,Census!$B:$B,"Female") -> 0
A33: Sr Dir Corporate Engineer | C33: =SUMIFS(Census!$H:$H,Census!$G:$G,$A33,Census!$B:$B,"Male") -> 0 | D33: =SUMIFS(Census!$H:$H,Census!$G:$G,$A33,Census!$B:$B,"Female") -> 221063.7
